[2025-07-09T05:31:56.339+0000] {local_task_job_runner.py:120} INFO - ::group::Pre task execution logs
[2025-07-09T05:31:56.357+0000] {taskinstance.py:2076} INFO - Dependencies all met for dep_context=non-requeueable deps ti=<TaskInstance: ETL_airflare_data.transform manual__2025-07-09T05:30:49.061743+00:00 map_index=0 [queued]>
[2025-07-09T05:31:56.364+0000] {taskinstance.py:2076} INFO - Dependencies all met for dep_context=requeueable deps ti=<TaskInstance: ETL_airflare_data.transform manual__2025-07-09T05:30:49.061743+00:00 map_index=0 [queued]>
[2025-07-09T05:31:56.364+0000] {taskinstance.py:2306} INFO - Starting attempt 2 of 3
[2025-07-09T05:31:56.375+0000] {taskinstance.py:2330} INFO - Executing <Mapped(_PythonDecoratedOperator): transform> on 2025-07-09 05:30:49.061743+00:00
[2025-07-09T05:31:56.385+0000] {warnings.py:112} WARNING - /home/***/.local/lib/python3.12/site-packages/***/task/task_runner/standard_task_runner.py:61: DeprecationWarning: This process (pid=4056) is multi-threaded, use of fork() may lead to deadlocks in the child.
  pid = os.fork()

[2025-07-09T05:31:56.387+0000] {standard_task_runner.py:63} INFO - Started process 4064 to run task
[2025-07-09T05:31:56.387+0000] {standard_task_runner.py:90} INFO - Running: ['***', 'tasks', 'run', 'ETL_airflare_data', 'transform', 'manual__2025-07-09T05:30:49.061743+00:00', '--job-id', '283', '--raw', '--subdir', 'DAGS_FOLDER/Untitled-1.py', '--cfg-path', '/tmp/tmpxf_wd0a3', '--map-index', '0']
[2025-07-09T05:31:56.388+0000] {standard_task_runner.py:91} INFO - Job 283: Subtask transform
[2025-07-09T05:31:56.437+0000] {task_command.py:426} INFO - Running <TaskInstance: ETL_airflare_data.transform manual__2025-07-09T05:30:49.061743+00:00 map_index=0 [running]> on host e6a32b72ede0
[2025-07-09T05:31:56.522+0000] {taskinstance.py:2648} INFO - Exporting env vars: AIRFLOW_CTX_DAG_OWNER='***' AIRFLOW_CTX_DAG_ID='ETL_airflare_data' AIRFLOW_CTX_TASK_ID='transform' AIRFLOW_CTX_EXECUTION_DATE='2025-07-09T05:30:49.061743+00:00' AIRFLOW_CTX_TRY_NUMBER='2' AIRFLOW_CTX_DAG_RUN_ID='manual__2025-07-09T05:30:49.061743+00:00'
[2025-07-09T05:31:56.524+0000] {taskinstance.py:430} INFO - ::endgroup::
[2025-07-09T05:31:56.534+0000] {Untitled-1.py:138} INFO - Данные приняты из Xcom, начат процесс очистки
[2025-07-09T05:31:56.536+0000] {taskinstance.py:441} INFO - ::group::Post task execution logs
[2025-07-09T05:31:56.536+0000] {taskinstance.py:2905} ERROR - Task failed with exception
Traceback (most recent call last):
  File "/home/airflow/.local/lib/python3.12/site-packages/airflow/models/taskinstance.py", line 465, in _execute_task
    result = _execute_callable(context=context, **execute_callable_kwargs)
             ^^^^^^^^^^^^^^^^^^^^^^^^^^^^^^^^^^^^^^^^^^^^^^^^^^^^^^^^^^^^^
  File "/home/airflow/.local/lib/python3.12/site-packages/airflow/models/taskinstance.py", line 432, in _execute_callable
    return execute_callable(context=context, **execute_callable_kwargs)
           ^^^^^^^^^^^^^^^^^^^^^^^^^^^^^^^^^^^^^^^^^^^^^^^^^^^^^^^^^^^^
  File "/home/airflow/.local/lib/python3.12/site-packages/airflow/models/baseoperator.py", line 401, in wrapper
    return func(self, *args, **kwargs)
           ^^^^^^^^^^^^^^^^^^^^^^^^^^^
  File "/home/airflow/.local/lib/python3.12/site-packages/airflow/decorators/base.py", line 265, in execute
    return_value = super().execute(context)
                   ^^^^^^^^^^^^^^^^^^^^^^^^
  File "/home/airflow/.local/lib/python3.12/site-packages/airflow/models/baseoperator.py", line 401, in wrapper
    return func(self, *args, **kwargs)
           ^^^^^^^^^^^^^^^^^^^^^^^^^^^
  File "/home/airflow/.local/lib/python3.12/site-packages/airflow/operators/python.py", line 235, in execute
    return_value = self.execute_callable()
                   ^^^^^^^^^^^^^^^^^^^^^^^
  File "/home/airflow/.local/lib/python3.12/site-packages/airflow/operators/python.py", line 252, in execute_callable
    return self.python_callable(*self.op_args, **self.op_kwargs)
           ^^^^^^^^^^^^^^^^^^^^^^^^^^^^^^^^^^^^^^^^^^^^^^^^^^^^^
  File "/opt/airflow/dags/Untitled-1.py", line 141, in transform
    file = load_from_s3(bucket=path['bucket'], key=path['key'])
                               ~~~~^^^^^^^^^^
  File "/home/airflow/.local/lib/python3.12/site-packages/airflow/models/xcom.py", line 801, in __getitem__
    raise ValueError("only support index access for now")
ValueError: only support index access for now
[2025-07-09T05:31:56.548+0000] {taskinstance.py:1206} INFO - Marking task as UP_FOR_RETRY. dag_id=ETL_airflare_data, task_id=transform, run_id=manual__2025-07-09T05:30:49.061743+00:00, map_index=0, execution_date=20250709T053049, start_date=20250709T053156, end_date=20250709T053156
[2025-07-09T05:31:56.558+0000] {standard_task_runner.py:110} ERROR - Failed to execute job 283 for task transform (only support index access for now; 4064)
[2025-07-09T05:31:56.601+0000] {local_task_job_runner.py:240} INFO - Task exited with return code 1
[2025-07-09T05:31:56.627+0000] {taskinstance.py:3503} INFO - 0 downstream tasks scheduled from follow-on schedule check
[2025-07-09T05:31:56.629+0000] {local_task_job_runner.py:222} INFO - ::endgroup::
