[2025-07-09T06:17:20.101+0000] {local_task_job_runner.py:120} INFO - ::group::Pre task execution logs
[2025-07-09T06:17:20.124+0000] {taskinstance.py:2076} INFO - Dependencies all met for dep_context=non-requeueable deps ti=<TaskInstance: ETL_airflare_data.load manual__2025-07-09T06:15:07.476264+00:00 map_index=6 [queued]>
[2025-07-09T06:17:20.134+0000] {taskinstance.py:2076} INFO - Dependencies all met for dep_context=requeueable deps ti=<TaskInstance: ETL_airflare_data.load manual__2025-07-09T06:15:07.476264+00:00 map_index=6 [queued]>
[2025-07-09T06:17:20.135+0000] {taskinstance.py:2306} INFO - Starting attempt 3 of 3
[2025-07-09T06:17:20.148+0000] {taskinstance.py:2330} INFO - Executing <Mapped(_PythonDecoratedOperator): load> on 2025-07-09 06:15:07.476264+00:00
[2025-07-09T06:17:20.159+0000] {warnings.py:112} WARNING - /home/***/.local/lib/python3.12/site-packages/***/task/task_runner/standard_task_runner.py:61: DeprecationWarning: This process (pid=5059) is multi-threaded, use of fork() may lead to deadlocks in the child.
  pid = os.fork()

[2025-07-09T06:17:20.161+0000] {standard_task_runner.py:63} INFO - Started process 5075 to run task
[2025-07-09T06:17:20.162+0000] {standard_task_runner.py:90} INFO - Running: ['***', 'tasks', 'run', 'ETL_airflare_data', 'load', 'manual__2025-07-09T06:15:07.476264+00:00', '--job-id', '404', '--raw', '--subdir', 'DAGS_FOLDER/Untitled-1.py', '--cfg-path', '/tmp/tmpdo9fclha', '--map-index', '6']
[2025-07-09T06:17:20.163+0000] {standard_task_runner.py:91} INFO - Job 404: Subtask load
[2025-07-09T06:17:20.238+0000] {task_command.py:426} INFO - Running <TaskInstance: ETL_airflare_data.load manual__2025-07-09T06:15:07.476264+00:00 map_index=6 [running]> on host e6a32b72ede0
[2025-07-09T06:17:20.375+0000] {taskinstance.py:2648} INFO - Exporting env vars: AIRFLOW_CTX_DAG_OWNER='***' AIRFLOW_CTX_DAG_ID='ETL_airflare_data' AIRFLOW_CTX_TASK_ID='load' AIRFLOW_CTX_EXECUTION_DATE='2025-07-09T06:15:07.476264+00:00' AIRFLOW_CTX_TRY_NUMBER='3' AIRFLOW_CTX_DAG_RUN_ID='manual__2025-07-09T06:15:07.476264+00:00'
[2025-07-09T06:17:20.377+0000] {taskinstance.py:430} INFO - ::endgroup::
[2025-07-09T06:17:20.377+0000] {Untitled-1.py:166} INFO - Данные из Xcom успешно выгружены, начинаю выгружать данные из S3
[2025-07-09T06:17:20.378+0000] {Untitled-1.py:58} INFO - Создание подключения к S3
[2025-07-09T06:17:20.378+0000] {Untitled-1.py:62} INFO - Подключение установлено, загрузка данных из S3
[2025-07-09T06:17:20.390+0000] {base.py:84} INFO - Using connection ID 'minio' for task execution.
[2025-07-09T06:17:20.391+0000] {connection_wrapper.py:384} INFO - AWS Connection (conn_id='minio', conn_type='aws') credentials retrieved from login and password.
[2025-07-09T06:17:20.584+0000] {Untitled-1.py:68} INFO - Данные выгружены из S3
[2025-07-09T06:17:20.586+0000] {taskinstance.py:441} INFO - ::group::Post task execution logs
[2025-07-09T06:17:20.587+0000] {taskinstance.py:2905} ERROR - Task failed with exception
Traceback (most recent call last):
  File "/home/airflow/.local/lib/python3.12/site-packages/airflow/models/taskinstance.py", line 465, in _execute_task
    result = _execute_callable(context=context, **execute_callable_kwargs)
             ^^^^^^^^^^^^^^^^^^^^^^^^^^^^^^^^^^^^^^^^^^^^^^^^^^^^^^^^^^^^^
  File "/home/airflow/.local/lib/python3.12/site-packages/airflow/models/taskinstance.py", line 432, in _execute_callable
    return execute_callable(context=context, **execute_callable_kwargs)
           ^^^^^^^^^^^^^^^^^^^^^^^^^^^^^^^^^^^^^^^^^^^^^^^^^^^^^^^^^^^^
  File "/home/airflow/.local/lib/python3.12/site-packages/airflow/models/baseoperator.py", line 401, in wrapper
    return func(self, *args, **kwargs)
           ^^^^^^^^^^^^^^^^^^^^^^^^^^^
  File "/home/airflow/.local/lib/python3.12/site-packages/airflow/decorators/base.py", line 265, in execute
    return_value = super().execute(context)
                   ^^^^^^^^^^^^^^^^^^^^^^^^
  File "/home/airflow/.local/lib/python3.12/site-packages/airflow/models/baseoperator.py", line 401, in wrapper
    return func(self, *args, **kwargs)
           ^^^^^^^^^^^^^^^^^^^^^^^^^^^
  File "/home/airflow/.local/lib/python3.12/site-packages/airflow/operators/python.py", line 235, in execute
    return_value = self.execute_callable()
                   ^^^^^^^^^^^^^^^^^^^^^^^
  File "/home/airflow/.local/lib/python3.12/site-packages/airflow/operators/python.py", line 252, in execute_callable
    return self.python_callable(*self.op_args, **self.op_kwargs)
           ^^^^^^^^^^^^^^^^^^^^^^^^^^^^^^^^^^^^^^^^^^^^^^^^^^^^^
  File "/opt/airflow/dags/Untitled-1.py", line 171, in load
    df = pd.DataFrame(content)
         ^^^^^^^^^^^^^^^^^^^^^
  File "/home/airflow/.local/lib/python3.12/site-packages/pandas/core/frame.py", line 841, in __init__
    raise ValueError("DataFrame constructor not properly called!")
ValueError: DataFrame constructor not properly called!
[2025-07-09T06:17:20.609+0000] {taskinstance.py:1206} INFO - Marking task as FAILED. dag_id=ETL_airflare_data, task_id=load, run_id=manual__2025-07-09T06:15:07.476264+00:00, map_index=6, execution_date=20250709T061507, start_date=20250709T061720, end_date=20250709T061720
[2025-07-09T06:17:20.630+0000] {standard_task_runner.py:110} ERROR - Failed to execute job 404 for task load (DataFrame constructor not properly called!; 5075)
[2025-07-09T06:17:20.696+0000] {local_task_job_runner.py:240} INFO - Task exited with return code 1
[2025-07-09T06:17:20.714+0000] {local_task_job_runner.py:222} INFO - ::endgroup::
