[2025-07-09T04:11:34.838+0000] {local_task_job_runner.py:120} INFO - ::group::Pre task execution logs
[2025-07-09T04:11:34.851+0000] {taskinstance.py:2076} INFO - Dependencies all met for dep_context=non-requeueable deps ti=<TaskInstance: ETL_airflare_data.extract manual__2025-07-09T04:10:30.176202+00:00 map_index=0 [queued]>
[2025-07-09T04:11:34.856+0000] {taskinstance.py:2076} INFO - Dependencies all met for dep_context=requeueable deps ti=<TaskInstance: ETL_airflare_data.extract manual__2025-07-09T04:10:30.176202+00:00 map_index=0 [queued]>
[2025-07-09T04:11:34.856+0000] {taskinstance.py:2306} INFO - Starting attempt 2 of 3
[2025-07-09T04:11:34.865+0000] {taskinstance.py:2330} INFO - Executing <Mapped(_PythonDecoratedOperator): extract> on 2025-07-09 04:10:30.176202+00:00
[2025-07-09T04:11:34.873+0000] {warnings.py:112} WARNING - /home/***/.local/lib/python3.12/site-packages/***/task/task_runner/standard_task_runner.py:61: DeprecationWarning: This process (pid=2908) is multi-threaded, use of fork() may lead to deadlocks in the child.
  pid = os.fork()

[2025-07-09T04:11:34.875+0000] {standard_task_runner.py:63} INFO - Started process 2911 to run task
[2025-07-09T04:11:34.875+0000] {standard_task_runner.py:90} INFO - Running: ['***', 'tasks', 'run', 'ETL_airflare_data', 'extract', 'manual__2025-07-09T04:10:30.176202+00:00', '--job-id', '257', '--raw', '--subdir', 'DAGS_FOLDER/Untitled-1.py', '--cfg-path', '/tmp/tmpzgwwld7d', '--map-index', '0']
[2025-07-09T04:11:34.876+0000] {standard_task_runner.py:91} INFO - Job 257: Subtask extract
[2025-07-09T04:11:34.924+0000] {task_command.py:426} INFO - Running <TaskInstance: ETL_airflare_data.extract manual__2025-07-09T04:10:30.176202+00:00 map_index=0 [running]> on host e6a32b72ede0
[2025-07-09T04:11:34.998+0000] {taskinstance.py:2648} INFO - Exporting env vars: AIRFLOW_CTX_DAG_OWNER='***' AIRFLOW_CTX_DAG_ID='ETL_airflare_data' AIRFLOW_CTX_TASK_ID='extract' AIRFLOW_CTX_EXECUTION_DATE='2025-07-09T04:10:30.176202+00:00' AIRFLOW_CTX_TRY_NUMBER='2' AIRFLOW_CTX_DAG_RUN_ID='manual__2025-07-09T04:10:30.176202+00:00'
[2025-07-09T04:11:35.001+0000] {taskinstance.py:430} INFO - ::endgroup::
[2025-07-09T04:11:35.002+0000] {Untitled-1.py:109} INFO - Начало извлечения данных для направления IKT-HKT
[2025-07-09T04:11:35.936+0000] {Untitled-1.py:26} INFO - Создание подключения к S3
[2025-07-09T04:11:35.937+0000] {Untitled-1.py:31} INFO - Подключение установлено
[2025-07-09T04:11:35.944+0000] {base.py:84} INFO - Using connection ID 'minio' for task execution.
[2025-07-09T04:11:35.945+0000] {connection_wrapper.py:384} INFO - AWS Connection (conn_id='minio', conn_type='aws') credentials retrieved from login and password.
[2025-07-09T04:11:36.272+0000] {Untitled-1.py:37} INFO - Загрузка данных в S3
[2025-07-09T04:11:36.272+0000] {taskinstance.py:441} INFO - ::group::Post task execution logs
[2025-07-09T04:11:36.273+0000] {taskinstance.py:2905} ERROR - Task failed with exception
Traceback (most recent call last):
  File "/home/airflow/.local/lib/python3.12/site-packages/airflow/models/taskinstance.py", line 465, in _execute_task
    result = _execute_callable(context=context, **execute_callable_kwargs)
             ^^^^^^^^^^^^^^^^^^^^^^^^^^^^^^^^^^^^^^^^^^^^^^^^^^^^^^^^^^^^^
  File "/home/airflow/.local/lib/python3.12/site-packages/airflow/models/taskinstance.py", line 432, in _execute_callable
    return execute_callable(context=context, **execute_callable_kwargs)
           ^^^^^^^^^^^^^^^^^^^^^^^^^^^^^^^^^^^^^^^^^^^^^^^^^^^^^^^^^^^^
  File "/home/airflow/.local/lib/python3.12/site-packages/airflow/models/baseoperator.py", line 401, in wrapper
    return func(self, *args, **kwargs)
           ^^^^^^^^^^^^^^^^^^^^^^^^^^^
  File "/home/airflow/.local/lib/python3.12/site-packages/airflow/decorators/base.py", line 265, in execute
    return_value = super().execute(context)
                   ^^^^^^^^^^^^^^^^^^^^^^^^
  File "/home/airflow/.local/lib/python3.12/site-packages/airflow/models/baseoperator.py", line 401, in wrapper
    return func(self, *args, **kwargs)
           ^^^^^^^^^^^^^^^^^^^^^^^^^^^
  File "/home/airflow/.local/lib/python3.12/site-packages/airflow/operators/python.py", line 235, in execute
    return_value = self.execute_callable()
                   ^^^^^^^^^^^^^^^^^^^^^^^
  File "/home/airflow/.local/lib/python3.12/site-packages/airflow/operators/python.py", line 252, in execute_callable
    return self.python_callable(*self.op_args, **self.op_kwargs)
           ^^^^^^^^^^^^^^^^^^^^^^^^^^^^^^^^^^^^^^^^^^^^^^^^^^^^^
  File "/opt/airflow/dags/Untitled-1.py", line 119, in extract
    path = upload_to_s3(response.json(),
           ^^^^^^^^^^^^^^^^^^^^^^^^^^^^^
  File "/opt/airflow/dags/Untitled-1.py", line 39, in upload_to_s3
    hook.load_string(  # Загружает строку в S3
  File "/home/airflow/.local/lib/python3.12/site-packages/airflow/providers/amazon/aws/hooks/s3.py", line 135, in wrapper
    return func(*bound_args.args, **bound_args.kwargs)
           ^^^^^^^^^^^^^^^^^^^^^^^^^^^^^^^^^^^^^^^^^^^
  File "/home/airflow/.local/lib/python3.12/site-packages/airflow/providers/amazon/aws/hooks/s3.py", line 89, in wrapper
    return func(*bound_args.args, **bound_args.kwargs)
           ^^^^^^^^^^^^^^^^^^^^^^^^^^^^^^^^^^^^^^^^^^^
  File "/home/airflow/.local/lib/python3.12/site-packages/airflow/providers/amazon/aws/hooks/s3.py", line 1136, in load_string
    bytes_data = string_data.encode(encoding)
                 ^^^^^^^^^^^^^^^^^^
AttributeError: 'dict' object has no attribute 'encode'
[2025-07-09T04:11:36.282+0000] {taskinstance.py:1206} INFO - Marking task as UP_FOR_RETRY. dag_id=ETL_airflare_data, task_id=extract, run_id=manual__2025-07-09T04:10:30.176202+00:00, map_index=0, execution_date=20250709T041030, start_date=20250709T041134, end_date=20250709T041136
[2025-07-09T04:11:36.293+0000] {standard_task_runner.py:110} ERROR - Failed to execute job 257 for task extract ('dict' object has no attribute 'encode'; 2911)
[2025-07-09T04:11:36.332+0000] {local_task_job_runner.py:240} INFO - Task exited with return code 1
[2025-07-09T04:11:36.364+0000] {taskinstance.py:3503} INFO - 0 downstream tasks scheduled from follow-on schedule check
[2025-07-09T04:11:36.366+0000] {local_task_job_runner.py:222} INFO - ::endgroup::
