[2025-07-07T09:13:27.638+0000] {local_task_job_runner.py:120} INFO - ::group::Pre task execution logs
[2025-07-07T09:13:27.651+0000] {taskinstance.py:2076} INFO - Dependencies all met for dep_context=non-requeueable deps ti=<TaskInstance: ETL_airflare_data.load manual__2025-07-07T09:12:20.150259+00:00 [queued]>
[2025-07-07T09:13:27.655+0000] {taskinstance.py:2076} INFO - Dependencies all met for dep_context=requeueable deps ti=<TaskInstance: ETL_airflare_data.load manual__2025-07-07T09:12:20.150259+00:00 [queued]>
[2025-07-07T09:13:27.656+0000] {taskinstance.py:2306} INFO - Starting attempt 2 of 3
[2025-07-07T09:13:27.665+0000] {taskinstance.py:2330} INFO - Executing <Task(PythonOperator): load> on 2025-07-07 09:12:20.150259+00:00
[2025-07-07T09:13:27.673+0000] {warnings.py:112} WARNING - /home/***/.local/lib/python3.12/site-packages/***/task/task_runner/standard_task_runner.py:61: DeprecationWarning: This process (pid=766) is multi-threaded, use of fork() may lead to deadlocks in the child.
  pid = os.fork()

[2025-07-07T09:13:27.675+0000] {standard_task_runner.py:90} INFO - Running: ['***', 'tasks', 'run', 'ETL_airflare_data', 'load', 'manual__2025-07-07T09:12:20.150259+00:00', '--job-id', '146', '--raw', '--subdir', 'DAGS_FOLDER/Untitled-1.py', '--cfg-path', '/tmp/tmpppkvcl2b']
[2025-07-07T09:13:27.677+0000] {standard_task_runner.py:63} INFO - Started process 768 to run task
[2025-07-07T09:13:27.677+0000] {standard_task_runner.py:91} INFO - Job 146: Subtask load
[2025-07-07T09:13:27.725+0000] {task_command.py:426} INFO - Running <TaskInstance: ETL_airflare_data.load manual__2025-07-07T09:12:20.150259+00:00 [running]> on host e6a32b72ede0
[2025-07-07T09:13:27.791+0000] {taskinstance.py:2648} INFO - Exporting env vars: AIRFLOW_CTX_DAG_OWNER='***' AIRFLOW_CTX_DAG_ID='ETL_airflare_data' AIRFLOW_CTX_TASK_ID='load' AIRFLOW_CTX_EXECUTION_DATE='2025-07-07T09:12:20.150259+00:00' AIRFLOW_CTX_TRY_NUMBER='2' AIRFLOW_CTX_DAG_RUN_ID='manual__2025-07-07T09:12:20.150259+00:00'
[2025-07-07T09:13:27.792+0000] {taskinstance.py:430} INFO - ::endgroup::
[2025-07-07T09:13:27.812+0000] {Untitled-1.py:121} INFO - Данные из Xcom успешно выгружены, начинаю выгружать данные из S3
[2025-07-07T09:13:27.814+0000] {Untitled-1.py:43} INFO - Создание подключения к S3
[2025-07-07T09:13:27.814+0000] {Untitled-1.py:46} INFO - Подключение установлено, загрузка данных из S3
[2025-07-07T09:13:27.822+0000] {base.py:84} INFO - Using connection ID 'minio' for task execution.
[2025-07-07T09:13:27.823+0000] {connection_wrapper.py:384} INFO - AWS Connection (conn_id='minio', conn_type='aws') credentials retrieved from login and password.
[2025-07-07T09:13:27.999+0000] {Untitled-1.py:51} INFO - Данные выгружены из S3
[2025-07-07T09:13:28.000+0000] {taskinstance.py:441} INFO - ::group::Post task execution logs
[2025-07-07T09:13:28.000+0000] {taskinstance.py:2905} ERROR - Task failed with exception
Traceback (most recent call last):
  File "/home/airflow/.local/lib/python3.12/site-packages/airflow/models/taskinstance.py", line 465, in _execute_task
    result = _execute_callable(context=context, **execute_callable_kwargs)
             ^^^^^^^^^^^^^^^^^^^^^^^^^^^^^^^^^^^^^^^^^^^^^^^^^^^^^^^^^^^^^
  File "/home/airflow/.local/lib/python3.12/site-packages/airflow/models/taskinstance.py", line 432, in _execute_callable
    return execute_callable(context=context, **execute_callable_kwargs)
           ^^^^^^^^^^^^^^^^^^^^^^^^^^^^^^^^^^^^^^^^^^^^^^^^^^^^^^^^^^^^
  File "/home/airflow/.local/lib/python3.12/site-packages/airflow/models/baseoperator.py", line 401, in wrapper
    return func(self, *args, **kwargs)
           ^^^^^^^^^^^^^^^^^^^^^^^^^^^
  File "/home/airflow/.local/lib/python3.12/site-packages/airflow/operators/python.py", line 235, in execute
    return_value = self.execute_callable()
                   ^^^^^^^^^^^^^^^^^^^^^^^
  File "/home/airflow/.local/lib/python3.12/site-packages/airflow/operators/python.py", line 252, in execute_callable
    return self.python_callable(*self.op_args, **self.op_kwargs)
           ^^^^^^^^^^^^^^^^^^^^^^^^^^^^^^^^^^^^^^^^^^^^^^^^^^^^^
  File "/opt/airflow/dags/Untitled-1.py", line 124, in load
    content = load_from_s3(bucket=path['bucket'], key=path['key'])
              ^^^^^^^^^^^^^^^^^^^^^^^^^^^^^^^^^^^^^^^^^^^^^^^^^^^^
  File "/opt/airflow/dags/Untitled-1.py", line 52, in load_from_s3
    return dict(data)
           ^^^^^^^^^^
ValueError: dictionary update sequence element #0 has length 1; 2 is required
[2025-07-07T09:13:28.010+0000] {taskinstance.py:1206} INFO - Marking task as UP_FOR_RETRY. dag_id=ETL_airflare_data, task_id=load, run_id=manual__2025-07-07T09:12:20.150259+00:00, execution_date=20250707T091220, start_date=20250707T091327, end_date=20250707T091328
[2025-07-07T09:13:28.020+0000] {standard_task_runner.py:110} ERROR - Failed to execute job 146 for task load (dictionary update sequence element #0 has length 1; 2 is required; 768)
[2025-07-07T09:13:28.052+0000] {local_task_job_runner.py:240} INFO - Task exited with return code 1
[2025-07-07T09:13:28.065+0000] {taskinstance.py:3503} INFO - 0 downstream tasks scheduled from follow-on schedule check
[2025-07-07T09:13:28.067+0000] {local_task_job_runner.py:222} INFO - ::endgroup::
