[2025-07-07T08:57:13.035+0000] {local_task_job_runner.py:120} INFO - ::group::Pre task execution logs
[2025-07-07T08:57:13.049+0000] {taskinstance.py:2076} INFO - Dependencies all met for dep_context=non-requeueable deps ti=<TaskInstance: ETL_airflare_data.load manual__2025-07-07T08:55:04.032845+00:00 [queued]>
[2025-07-07T08:57:13.054+0000] {taskinstance.py:2076} INFO - Dependencies all met for dep_context=requeueable deps ti=<TaskInstance: ETL_airflare_data.load manual__2025-07-07T08:55:04.032845+00:00 [queued]>
[2025-07-07T08:57:13.054+0000] {taskinstance.py:2306} INFO - Starting attempt 3 of 3
[2025-07-07T08:57:13.063+0000] {taskinstance.py:2330} INFO - Executing <Task(PythonOperator): load> on 2025-07-07 08:55:04.032845+00:00
[2025-07-07T08:57:13.071+0000] {warnings.py:112} WARNING - /home/***/.local/lib/python3.12/site-packages/***/task/task_runner/standard_task_runner.py:61: DeprecationWarning: This process (pid=502) is multi-threaded, use of fork() may lead to deadlocks in the child.
  pid = os.fork()

[2025-07-07T08:57:13.074+0000] {standard_task_runner.py:63} INFO - Started process 504 to run task
[2025-07-07T08:57:13.073+0000] {standard_task_runner.py:90} INFO - Running: ['***', 'tasks', 'run', 'ETL_airflare_data', 'load', 'manual__2025-07-07T08:55:04.032845+00:00', '--job-id', '132', '--raw', '--subdir', 'DAGS_FOLDER/Untitled-1.py', '--cfg-path', '/tmp/tmp5n3qm0ve']
[2025-07-07T08:57:13.075+0000] {standard_task_runner.py:91} INFO - Job 132: Subtask load
[2025-07-07T08:57:13.123+0000] {task_command.py:426} INFO - Running <TaskInstance: ETL_airflare_data.load manual__2025-07-07T08:55:04.032845+00:00 [running]> on host e6a32b72ede0
[2025-07-07T08:57:13.190+0000] {taskinstance.py:2648} INFO - Exporting env vars: AIRFLOW_CTX_DAG_OWNER='***' AIRFLOW_CTX_DAG_ID='ETL_airflare_data' AIRFLOW_CTX_TASK_ID='load' AIRFLOW_CTX_EXECUTION_DATE='2025-07-07T08:55:04.032845+00:00' AIRFLOW_CTX_TRY_NUMBER='3' AIRFLOW_CTX_DAG_RUN_ID='manual__2025-07-07T08:55:04.032845+00:00'
[2025-07-07T08:57:13.191+0000] {taskinstance.py:430} INFO - ::endgroup::
[2025-07-07T08:57:13.210+0000] {taskinstance.py:441} INFO - ::group::Post task execution logs
[2025-07-07T08:57:13.210+0000] {taskinstance.py:2905} ERROR - Task failed with exception
Traceback (most recent call last):
  File "/home/airflow/.local/lib/python3.12/site-packages/airflow/models/taskinstance.py", line 465, in _execute_task
    result = _execute_callable(context=context, **execute_callable_kwargs)
             ^^^^^^^^^^^^^^^^^^^^^^^^^^^^^^^^^^^^^^^^^^^^^^^^^^^^^^^^^^^^^
  File "/home/airflow/.local/lib/python3.12/site-packages/airflow/models/taskinstance.py", line 432, in _execute_callable
    return execute_callable(context=context, **execute_callable_kwargs)
           ^^^^^^^^^^^^^^^^^^^^^^^^^^^^^^^^^^^^^^^^^^^^^^^^^^^^^^^^^^^^
  File "/home/airflow/.local/lib/python3.12/site-packages/airflow/models/baseoperator.py", line 401, in wrapper
    return func(self, *args, **kwargs)
           ^^^^^^^^^^^^^^^^^^^^^^^^^^^
  File "/home/airflow/.local/lib/python3.12/site-packages/airflow/operators/python.py", line 235, in execute
    return_value = self.execute_callable()
                   ^^^^^^^^^^^^^^^^^^^^^^^
  File "/home/airflow/.local/lib/python3.12/site-packages/airflow/operators/python.py", line 252, in execute_callable
    return self.python_callable(*self.op_args, **self.op_kwargs)
           ^^^^^^^^^^^^^^^^^^^^^^^^^^^^^^^^^^^^^^^^^^^^^^^^^^^^^
  File "/opt/airflow/dags/Untitled-1.py", line 121, in load
    df = pd.DataFrame(context['ti'].xcom_pull(key='path'))
         ^^^^^^^^^^^^^^^^^^^^^^^^^^^^^^^^^^^^^^^^^^^^^^^^^
  File "/home/airflow/.local/lib/python3.12/site-packages/pandas/core/frame.py", line 841, in __init__
    raise ValueError("DataFrame constructor not properly called!")
ValueError: DataFrame constructor not properly called!
[2025-07-07T08:57:13.222+0000] {taskinstance.py:1206} INFO - Marking task as FAILED. dag_id=ETL_airflare_data, task_id=load, run_id=manual__2025-07-07T08:55:04.032845+00:00, execution_date=20250707T085504, start_date=20250707T085713, end_date=20250707T085713
[2025-07-07T08:57:13.232+0000] {standard_task_runner.py:110} ERROR - Failed to execute job 132 for task load (DataFrame constructor not properly called!; 504)
[2025-07-07T08:57:13.248+0000] {local_task_job_runner.py:240} INFO - Task exited with return code 1
[2025-07-07T08:57:13.262+0000] {taskinstance.py:3503} INFO - 0 downstream tasks scheduled from follow-on schedule check
[2025-07-07T08:57:13.264+0000] {local_task_job_runner.py:222} INFO - ::endgroup::
