[2025-07-09T04:12:37.292+0000] {local_task_job_runner.py:120} INFO - ::group::Pre task execution logs
[2025-07-09T04:12:37.307+0000] {taskinstance.py:2076} INFO - Dependencies all met for dep_context=non-requeueable deps ti=<TaskInstance: ETL_airflare_data.extract manual__2025-07-09T04:10:30.176202+00:00 map_index=1 [queued]>
[2025-07-09T04:12:37.313+0000] {taskinstance.py:2076} INFO - Dependencies all met for dep_context=requeueable deps ti=<TaskInstance: ETL_airflare_data.extract manual__2025-07-09T04:10:30.176202+00:00 map_index=1 [queued]>
[2025-07-09T04:12:37.313+0000] {taskinstance.py:2306} INFO - Starting attempt 3 of 3
[2025-07-09T04:12:37.322+0000] {taskinstance.py:2330} INFO - Executing <Mapped(_PythonDecoratedOperator): extract> on 2025-07-09 04:10:30.176202+00:00
[2025-07-09T04:12:37.330+0000] {warnings.py:112} WARNING - /home/***/.local/lib/python3.12/site-packages/***/task/task_runner/standard_task_runner.py:61: DeprecationWarning: This process (pid=2928) is multi-threaded, use of fork() may lead to deadlocks in the child.
  pid = os.fork()

[2025-07-09T04:12:37.332+0000] {standard_task_runner.py:63} INFO - Started process 2931 to run task
[2025-07-09T04:12:37.332+0000] {standard_task_runner.py:90} INFO - Running: ['***', 'tasks', 'run', 'ETL_airflare_data', 'extract', 'manual__2025-07-09T04:10:30.176202+00:00', '--job-id', '259', '--raw', '--subdir', 'DAGS_FOLDER/Untitled-1.py', '--cfg-path', '/tmp/tmpr301xnql', '--map-index', '1']
[2025-07-09T04:12:37.333+0000] {standard_task_runner.py:91} INFO - Job 259: Subtask extract
[2025-07-09T04:12:37.380+0000] {task_command.py:426} INFO - Running <TaskInstance: ETL_airflare_data.extract manual__2025-07-09T04:10:30.176202+00:00 map_index=1 [running]> on host e6a32b72ede0
[2025-07-09T04:12:37.457+0000] {taskinstance.py:2648} INFO - Exporting env vars: AIRFLOW_CTX_DAG_OWNER='***' AIRFLOW_CTX_DAG_ID='ETL_airflare_data' AIRFLOW_CTX_TASK_ID='extract' AIRFLOW_CTX_EXECUTION_DATE='2025-07-09T04:10:30.176202+00:00' AIRFLOW_CTX_TRY_NUMBER='3' AIRFLOW_CTX_DAG_RUN_ID='manual__2025-07-09T04:10:30.176202+00:00'
[2025-07-09T04:12:37.460+0000] {taskinstance.py:430} INFO - ::endgroup::
[2025-07-09T04:12:37.460+0000] {Untitled-1.py:109} INFO - Начало извлечения данных для направления HKT-IKT
[2025-07-09T04:12:39.320+0000] {Untitled-1.py:26} INFO - Создание подключения к S3
[2025-07-09T04:12:39.321+0000] {Untitled-1.py:31} INFO - Подключение установлено
[2025-07-09T04:12:39.329+0000] {base.py:84} INFO - Using connection ID 'minio' for task execution.
[2025-07-09T04:12:39.330+0000] {connection_wrapper.py:384} INFO - AWS Connection (conn_id='minio', conn_type='aws') credentials retrieved from login and password.
[2025-07-09T04:12:39.621+0000] {Untitled-1.py:37} INFO - Загрузка данных в S3
[2025-07-09T04:12:39.621+0000] {taskinstance.py:441} INFO - ::group::Post task execution logs
[2025-07-09T04:12:39.622+0000] {taskinstance.py:2905} ERROR - Task failed with exception
Traceback (most recent call last):
  File "/home/airflow/.local/lib/python3.12/site-packages/airflow/models/taskinstance.py", line 465, in _execute_task
    result = _execute_callable(context=context, **execute_callable_kwargs)
             ^^^^^^^^^^^^^^^^^^^^^^^^^^^^^^^^^^^^^^^^^^^^^^^^^^^^^^^^^^^^^
  File "/home/airflow/.local/lib/python3.12/site-packages/airflow/models/taskinstance.py", line 432, in _execute_callable
    return execute_callable(context=context, **execute_callable_kwargs)
           ^^^^^^^^^^^^^^^^^^^^^^^^^^^^^^^^^^^^^^^^^^^^^^^^^^^^^^^^^^^^
  File "/home/airflow/.local/lib/python3.12/site-packages/airflow/models/baseoperator.py", line 401, in wrapper
    return func(self, *args, **kwargs)
           ^^^^^^^^^^^^^^^^^^^^^^^^^^^
  File "/home/airflow/.local/lib/python3.12/site-packages/airflow/decorators/base.py", line 265, in execute
    return_value = super().execute(context)
                   ^^^^^^^^^^^^^^^^^^^^^^^^
  File "/home/airflow/.local/lib/python3.12/site-packages/airflow/models/baseoperator.py", line 401, in wrapper
    return func(self, *args, **kwargs)
           ^^^^^^^^^^^^^^^^^^^^^^^^^^^
  File "/home/airflow/.local/lib/python3.12/site-packages/airflow/operators/python.py", line 235, in execute
    return_value = self.execute_callable()
                   ^^^^^^^^^^^^^^^^^^^^^^^
  File "/home/airflow/.local/lib/python3.12/site-packages/airflow/operators/python.py", line 252, in execute_callable
    return self.python_callable(*self.op_args, **self.op_kwargs)
           ^^^^^^^^^^^^^^^^^^^^^^^^^^^^^^^^^^^^^^^^^^^^^^^^^^^^^
  File "/opt/airflow/dags/Untitled-1.py", line 119, in extract
    path = upload_to_s3(response.json(),
           ^^^^^^^^^^^^^^^^^^^^^^^^^^^^^
  File "/opt/airflow/dags/Untitled-1.py", line 39, in upload_to_s3
    hook.load_string(  # Загружает строку в S3
  File "/home/airflow/.local/lib/python3.12/site-packages/airflow/providers/amazon/aws/hooks/s3.py", line 135, in wrapper
    return func(*bound_args.args, **bound_args.kwargs)
           ^^^^^^^^^^^^^^^^^^^^^^^^^^^^^^^^^^^^^^^^^^^
  File "/home/airflow/.local/lib/python3.12/site-packages/airflow/providers/amazon/aws/hooks/s3.py", line 89, in wrapper
    return func(*bound_args.args, **bound_args.kwargs)
           ^^^^^^^^^^^^^^^^^^^^^^^^^^^^^^^^^^^^^^^^^^^
  File "/home/airflow/.local/lib/python3.12/site-packages/airflow/providers/amazon/aws/hooks/s3.py", line 1136, in load_string
    bytes_data = string_data.encode(encoding)
                 ^^^^^^^^^^^^^^^^^^
AttributeError: 'dict' object has no attribute 'encode'
[2025-07-09T04:12:39.630+0000] {taskinstance.py:1206} INFO - Marking task as FAILED. dag_id=ETL_airflare_data, task_id=extract, run_id=manual__2025-07-09T04:10:30.176202+00:00, map_index=1, execution_date=20250709T041030, start_date=20250709T041237, end_date=20250709T041239
[2025-07-09T04:12:39.640+0000] {standard_task_runner.py:110} ERROR - Failed to execute job 259 for task extract ('dict' object has no attribute 'encode'; 2931)
[2025-07-09T04:12:39.671+0000] {local_task_job_runner.py:240} INFO - Task exited with return code 1
[2025-07-09T04:12:39.687+0000] {taskinstance.py:3503} INFO - 0 downstream tasks scheduled from follow-on schedule check
[2025-07-09T04:12:39.689+0000] {local_task_job_runner.py:222} INFO - ::endgroup::
