[2025-07-09T05:48:28.999+0000] {local_task_job_runner.py:120} INFO - ::group::Pre task execution logs
[2025-07-09T05:48:29.013+0000] {taskinstance.py:2076} INFO - Dependencies all met for dep_context=non-requeueable deps ti=<TaskInstance: ETL_airflare_data.extract manual__2025-07-09T05:48:27.734871+00:00 map_index=1 [queued]>
[2025-07-09T05:48:29.018+0000] {taskinstance.py:2076} INFO - Dependencies all met for dep_context=requeueable deps ti=<TaskInstance: ETL_airflare_data.extract manual__2025-07-09T05:48:27.734871+00:00 map_index=1 [queued]>
[2025-07-09T05:48:29.019+0000] {taskinstance.py:2306} INFO - Starting attempt 1 of 3
[2025-07-09T05:48:29.028+0000] {taskinstance.py:2330} INFO - Executing <Mapped(_PythonDecoratedOperator): extract> on 2025-07-09 05:48:27.734871+00:00
[2025-07-09T05:48:29.036+0000] {warnings.py:112} WARNING - /home/***/.local/lib/python3.12/site-packages/***/task/task_runner/standard_task_runner.py:61: DeprecationWarning: This process (pid=4411) is multi-threaded, use of fork() may lead to deadlocks in the child.
  pid = os.fork()

[2025-07-09T05:48:29.037+0000] {standard_task_runner.py:63} INFO - Started process 4415 to run task
[2025-07-09T05:48:29.038+0000] {standard_task_runner.py:90} INFO - Running: ['***', 'tasks', 'run', 'ETL_airflare_data', 'extract', 'manual__2025-07-09T05:48:27.734871+00:00', '--job-id', '323', '--raw', '--subdir', 'DAGS_FOLDER/Untitled-1.py', '--cfg-path', '/tmp/tmp48zmqqlg', '--map-index', '1']
[2025-07-09T05:48:29.039+0000] {standard_task_runner.py:91} INFO - Job 323: Subtask extract
[2025-07-09T05:48:29.093+0000] {task_command.py:426} INFO - Running <TaskInstance: ETL_airflare_data.extract manual__2025-07-09T05:48:27.734871+00:00 map_index=1 [running]> on host e6a32b72ede0
[2025-07-09T05:48:29.174+0000] {taskinstance.py:2648} INFO - Exporting env vars: AIRFLOW_CTX_DAG_OWNER='***' AIRFLOW_CTX_DAG_ID='ETL_airflare_data' AIRFLOW_CTX_TASK_ID='extract' AIRFLOW_CTX_EXECUTION_DATE='2025-07-09T05:48:27.734871+00:00' AIRFLOW_CTX_TRY_NUMBER='1' AIRFLOW_CTX_DAG_RUN_ID='manual__2025-07-09T05:48:27.734871+00:00'
[2025-07-09T05:48:29.177+0000] {taskinstance.py:430} INFO - ::endgroup::
[2025-07-09T05:48:29.178+0000] {Untitled-1.py:111} INFO - Начало извлечения данных для направления HKT-IKT
[2025-07-09T05:48:51.360+0000] {Untitled-1.py:117} ERROR - Ошибка при чтении данных из API
[2025-07-09T05:48:51.360+0000] {taskinstance.py:441} INFO - ::group::Post task execution logs
[2025-07-09T05:48:51.361+0000] {taskinstance.py:2905} ERROR - Task failed with exception
Traceback (most recent call last):
  File "/home/airflow/.local/lib/python3.12/site-packages/airflow/models/taskinstance.py", line 465, in _execute_task
    result = _execute_callable(context=context, **execute_callable_kwargs)
             ^^^^^^^^^^^^^^^^^^^^^^^^^^^^^^^^^^^^^^^^^^^^^^^^^^^^^^^^^^^^^
  File "/home/airflow/.local/lib/python3.12/site-packages/airflow/models/taskinstance.py", line 432, in _execute_callable
    return execute_callable(context=context, **execute_callable_kwargs)
           ^^^^^^^^^^^^^^^^^^^^^^^^^^^^^^^^^^^^^^^^^^^^^^^^^^^^^^^^^^^^
  File "/home/airflow/.local/lib/python3.12/site-packages/airflow/models/baseoperator.py", line 401, in wrapper
    return func(self, *args, **kwargs)
           ^^^^^^^^^^^^^^^^^^^^^^^^^^^
  File "/home/airflow/.local/lib/python3.12/site-packages/airflow/decorators/base.py", line 265, in execute
    return_value = super().execute(context)
                   ^^^^^^^^^^^^^^^^^^^^^^^^
  File "/home/airflow/.local/lib/python3.12/site-packages/airflow/models/baseoperator.py", line 401, in wrapper
    return func(self, *args, **kwargs)
           ^^^^^^^^^^^^^^^^^^^^^^^^^^^
  File "/home/airflow/.local/lib/python3.12/site-packages/airflow/operators/python.py", line 235, in execute
    return_value = self.execute_callable()
                   ^^^^^^^^^^^^^^^^^^^^^^^
  File "/home/airflow/.local/lib/python3.12/site-packages/airflow/operators/python.py", line 252, in execute_callable
    return self.python_callable(*self.op_args, **self.op_kwargs)
           ^^^^^^^^^^^^^^^^^^^^^^^^^^^^^^^^^^^^^^^^^^^^^^^^^^^^^
  File "/opt/airflow/dags/Untitled-1.py", line 118, in extract
    raise ValueError('Ошибка')
ValueError: Ошибка
[2025-07-09T05:48:51.372+0000] {taskinstance.py:1206} INFO - Marking task as UP_FOR_RETRY. dag_id=ETL_airflare_data, task_id=extract, run_id=manual__2025-07-09T05:48:27.734871+00:00, map_index=1, execution_date=20250709T054827, start_date=20250709T054829, end_date=20250709T054851
[2025-07-09T05:48:51.386+0000] {standard_task_runner.py:110} ERROR - Failed to execute job 323 for task extract (Ошибка; 4415)
[2025-07-09T05:48:51.424+0000] {local_task_job_runner.py:240} INFO - Task exited with return code 1
[2025-07-09T05:48:51.431+0000] {local_task_job_runner.py:222} INFO - ::endgroup::
